2025-03-21 13:35:45,888 - WARNING - log - log_response - Not Found: /
2025-03-21 13:35:57,111 - ERROR - log - log_response - Internal Server Error: /search/
Traceback (most recent call last):
  File "/usr/local/lib/python3.11/site-packages/django/core/handlers/exception.py", line 55, in inner
    response = get_response(request)
               ^^^^^^^^^^^^^^^^^^^^^
  File "/usr/local/lib/python3.11/site-packages/django/core/handlers/base.py", line 197, in _get_response
    response = wrapped_callback(request, *callback_args, **callback_kwargs)
               ^^^^^^^^^^^^^^^^^^^^^^^^^^^^^^^^^^^^^^^^^^^^^^^^^^^^^^^^^^^^
  File "/app/scraper_project/scraper/views.py", line 31, in job_search
    driver = webdriver.Firefox(service=service, options=options)
             ^^^^^^^^^^^^^^^^^^^^^^^^^^^^^^^^^^^^^^^^^^^^^^^^^^^
  File "/usr/local/lib/python3.11/site-packages/selenium/webdriver/firefox/webdriver.py", line 71, in __init__
    super().__init__(command_executor=executor, options=options)
  File "/usr/local/lib/python3.11/site-packages/selenium/webdriver/remote/webdriver.py", line 250, in __init__
    self.start_session(capabilities)
  File "/usr/local/lib/python3.11/site-packages/selenium/webdriver/remote/webdriver.py", line 342, in start_session
    response = self.execute(Command.NEW_SESSION, caps)["value"]
               ^^^^^^^^^^^^^^^^^^^^^^^^^^^^^^^^^^^^^^^
  File "/usr/local/lib/python3.11/site-packages/selenium/webdriver/remote/webdriver.py", line 429, in execute
    self.error_handler.check_response(response)
  File "/usr/local/lib/python3.11/site-packages/selenium/webdriver/remote/errorhandler.py", line 232, in check_response
    raise exception_class(message, screen, stacktrace)
selenium.common.exceptions.WebDriverException: Message: Process unexpectedly closed with status 1

